2022-02-01 15:30:27,019 INFO    MainThread:163113 [internal.py:wandb_internal():91] W&B internal server running at pid: 163113, started at: 2022-02-01 15:30:27.018955
2022-02-01 15:30:27,020 INFO    WriterThread:163113 [datastore.py:open_for_write():77] open: /home/sebastian/Desktop/pytorchrl/wandb/run-20220201_153026-1on9yqq3/run-1on9yqq3.wandb
2022-02-01 15:30:27,021 DEBUG   HandlerThread:163113 [handler.py:handle_request():101] handle_request: check_version
2022-02-01 15:30:27,022 DEBUG   SenderThread:163113 [sender.py:send():122] send: header
2022-02-01 15:30:27,022 DEBUG   SenderThread:163113 [sender.py:send():122] send: request
2022-02-01 15:30:27,022 DEBUG   SenderThread:163113 [sender.py:send_request():131] send_request: check_version
2022-02-01 15:30:27,133 DEBUG   SenderThread:163113 [sender.py:send():122] send: run
2022-02-01 15:30:27,399 INFO    SenderThread:163113 [sender.py:_start_run_threads():599] run started: 1on9yqq3 with start time 1643725826
2022-02-01 15:30:27,405 DEBUG   SenderThread:163113 [sender.py:send():122] send: summary
2022-02-01 15:30:27,405 INFO    SenderThread:163113 [sender.py:_save_file():730] saving file wandb-summary.json with policy end
2022-02-01 15:30:27,408 DEBUG   HandlerThread:163113 [handler.py:handle_request():101] handle_request: run_start
2022-02-01 15:30:29,824 DEBUG   HandlerThread:163113 [meta.py:__init__():34] meta init
2022-02-01 15:30:29,825 DEBUG   HandlerThread:163113 [meta.py:__init__():48] meta init done
2022-02-01 15:30:29,825 DEBUG   HandlerThread:163113 [meta.py:probe():190] probe
2022-02-01 15:30:29,832 DEBUG   HandlerThread:163113 [meta.py:_setup_git():180] setup git
2022-02-01 15:30:29,888 DEBUG   HandlerThread:163113 [meta.py:_setup_git():187] setup git done
2022-02-01 15:30:29,889 DEBUG   HandlerThread:163113 [meta.py:_save_pip():52] save pip
2022-02-01 15:30:29,889 DEBUG   HandlerThread:163113 [meta.py:_save_pip():66] save pip done
2022-02-01 15:30:29,890 DEBUG   HandlerThread:163113 [meta.py:probe():231] probe done
2022-02-01 15:30:29,895 DEBUG   SenderThread:163113 [sender.py:send():122] send: files
2022-02-01 15:30:29,895 INFO    SenderThread:163113 [sender.py:_save_file():730] saving file wandb-metadata.json with policy now
2022-02-01 15:30:29,902 DEBUG   HandlerThread:163113 [handler.py:handle_request():101] handle_request: status
2022-02-01 15:30:29,903 DEBUG   SenderThread:163113 [sender.py:send():122] send: request
2022-02-01 15:30:29,903 DEBUG   SenderThread:163113 [sender.py:send_request():131] send_request: status
2022-02-01 15:30:36,156 DEBUG   SenderThread:163113 [sender.py:send():122] send: stats
2022-02-01 15:31:22,200 DEBUG   HandlerThread:163113 [handler.py:handle_request():101] handle_request: status
2022-02-01 15:31:22,594 DEBUG   SenderThread:163113 [sender.py:send():122] send: request
2022-02-01 15:31:24,460 DEBUG   SenderThread:163113 [sender.py:send_request():131] send_request: status
2022-02-01 15:31:35,798 DEBUG   SenderThread:163113 [sender.py:send():122] send: stats
2022-02-01 15:31:44,996 DEBUG   SenderThread:163113 [sender.py:send():122] send: stats
2022-02-01 15:32:18,888 DEBUG   HandlerThread:163113 [handler.py:handle_request():101] handle_request: status
2022-02-01 15:32:21,128 DEBUG   SenderThread:163113 [sender.py:send():122] send: request
2022-02-01 15:32:21,453 DEBUG   SenderThread:163113 [sender.py:send_request():131] send_request: status
2022-02-01 15:34:56,806 ERROR   SenderThread:163113 [retry.py:__call__():111] Retry attempt failed:
Traceback (most recent call last):
  File "/home/sebastian/anaconda3/envs/rrc_simulation/lib/python3.7/site-packages/urllib3/connectionpool.py", line 706, in urlopen
    chunked=chunked,
  File "/home/sebastian/anaconda3/envs/rrc_simulation/lib/python3.7/site-packages/urllib3/connectionpool.py", line 382, in _make_request
    self._validate_conn(conn)
  File "/home/sebastian/anaconda3/envs/rrc_simulation/lib/python3.7/site-packages/urllib3/connectionpool.py", line 1010, in _validate_conn
    conn.connect()
  File "/home/sebastian/anaconda3/envs/rrc_simulation/lib/python3.7/site-packages/urllib3/connection.py", line 421, in connect
    tls_in_tls=tls_in_tls,
  File "/home/sebastian/anaconda3/envs/rrc_simulation/lib/python3.7/site-packages/urllib3/util/ssl_.py", line 429, in ssl_wrap_socket
    sock, context, tls_in_tls, server_hostname=server_hostname
  File "/home/sebastian/anaconda3/envs/rrc_simulation/lib/python3.7/site-packages/urllib3/util/ssl_.py", line 472, in _ssl_wrap_socket_impl
    return ssl_context.wrap_socket(sock, server_hostname=server_hostname)
  File "/home/sebastian/anaconda3/envs/rrc_simulation/lib/python3.7/ssl.py", line 423, in wrap_socket
    session=session
  File "/home/sebastian/anaconda3/envs/rrc_simulation/lib/python3.7/ssl.py", line 870, in _create
    self.do_handshake()
  File "/home/sebastian/anaconda3/envs/rrc_simulation/lib/python3.7/ssl.py", line 1139, in do_handshake
    self._sslobj.do_handshake()
OSError: [Errno 0] Error

During handling of the above exception, another exception occurred:

Traceback (most recent call last):
  File "/home/sebastian/anaconda3/envs/rrc_simulation/lib/python3.7/site-packages/requests/adapters.py", line 449, in send
    timeout=timeout
  File "/home/sebastian/anaconda3/envs/rrc_simulation/lib/python3.7/site-packages/urllib3/connectionpool.py", line 756, in urlopen
    method, url, error=e, _pool=self, _stacktrace=sys.exc_info()[2]
  File "/home/sebastian/anaconda3/envs/rrc_simulation/lib/python3.7/site-packages/urllib3/util/retry.py", line 531, in increment
    raise six.reraise(type(error), error, _stacktrace)
  File "/home/sebastian/anaconda3/envs/rrc_simulation/lib/python3.7/site-packages/urllib3/packages/six.py", line 734, in reraise
    raise value.with_traceback(tb)
  File "/home/sebastian/anaconda3/envs/rrc_simulation/lib/python3.7/site-packages/urllib3/connectionpool.py", line 706, in urlopen
    chunked=chunked,
  File "/home/sebastian/anaconda3/envs/rrc_simulation/lib/python3.7/site-packages/urllib3/connectionpool.py", line 382, in _make_request
    self._validate_conn(conn)
  File "/home/sebastian/anaconda3/envs/rrc_simulation/lib/python3.7/site-packages/urllib3/connectionpool.py", line 1010, in _validate_conn
    conn.connect()
  File "/home/sebastian/anaconda3/envs/rrc_simulation/lib/python3.7/site-packages/urllib3/connection.py", line 421, in connect
    tls_in_tls=tls_in_tls,
  File "/home/sebastian/anaconda3/envs/rrc_simulation/lib/python3.7/site-packages/urllib3/util/ssl_.py", line 429, in ssl_wrap_socket
    sock, context, tls_in_tls, server_hostname=server_hostname
  File "/home/sebastian/anaconda3/envs/rrc_simulation/lib/python3.7/site-packages/urllib3/util/ssl_.py", line 472, in _ssl_wrap_socket_impl
    return ssl_context.wrap_socket(sock, server_hostname=server_hostname)
  File "/home/sebastian/anaconda3/envs/rrc_simulation/lib/python3.7/ssl.py", line 423, in wrap_socket
    session=session
  File "/home/sebastian/anaconda3/envs/rrc_simulation/lib/python3.7/ssl.py", line 870, in _create
    self.do_handshake()
  File "/home/sebastian/anaconda3/envs/rrc_simulation/lib/python3.7/ssl.py", line 1139, in do_handshake
    self._sslobj.do_handshake()
urllib3.exceptions.ProtocolError: ('Connection aborted.', OSError(0, 'Error'))

During handling of the above exception, another exception occurred:

Traceback (most recent call last):
  File "/home/sebastian/anaconda3/envs/rrc_simulation/lib/python3.7/site-packages/wandb/old/retry.py", line 96, in __call__
    result = self._call_fn(*args, **kwargs)
  File "/home/sebastian/anaconda3/envs/rrc_simulation/lib/python3.7/site-packages/wandb/sdk/internal/internal_api.py", line 123, in execute
    return self.client.execute(*args, **kwargs)
  File "/home/sebastian/anaconda3/envs/rrc_simulation/lib/python3.7/site-packages/wandb/vendor/gql-0.2.0/gql/client.py", line 52, in execute
    result = self._get_result(document, *args, **kwargs)
  File "/home/sebastian/anaconda3/envs/rrc_simulation/lib/python3.7/site-packages/wandb/vendor/gql-0.2.0/gql/client.py", line 60, in _get_result
    return self.transport.execute(document, *args, **kwargs)
  File "/home/sebastian/anaconda3/envs/rrc_simulation/lib/python3.7/site-packages/wandb/vendor/gql-0.2.0/gql/transport/requests.py", line 38, in execute
    request = requests.post(self.url, **post_args)
  File "/home/sebastian/anaconda3/envs/rrc_simulation/lib/python3.7/site-packages/requests/api.py", line 119, in post
    return request('post', url, data=data, json=json, **kwargs)
  File "/home/sebastian/anaconda3/envs/rrc_simulation/lib/python3.7/site-packages/requests/api.py", line 61, in request
    return session.request(method=method, url=url, **kwargs)
  File "/home/sebastian/anaconda3/envs/rrc_simulation/lib/python3.7/site-packages/requests/sessions.py", line 542, in request
    resp = self.send(prep, **send_kwargs)
  File "/home/sebastian/anaconda3/envs/rrc_simulation/lib/python3.7/site-packages/requests/sessions.py", line 655, in send
    r = adapter.send(request, **kwargs)
  File "/home/sebastian/anaconda3/envs/rrc_simulation/lib/python3.7/site-packages/requests/adapters.py", line 498, in send
    raise ConnectionError(err, request=request)
requests.exceptions.ConnectionError: ('Connection aborted.', OSError(0, 'Error'))
